<?xml version="1.0" encoding="UTF-8"?>
<testng-results ignored="0" total="5" passed="1" failed="1" skipped="3">
  <reporter-output>
  </reporter-output>
  <suite started-at="2024-03-01T07:24:48Z" name="Suite" finished-at="2024-03-01T07:25:09Z" duration-ms="21730">
    <groups>
      <group name="Purchase">
        <method signature="SubmitOrderTest.submitOrder(java.util.HashMap)[pri:0, instance:jayasuriyapractice.SubmitOrderTest@21337f7b]" name="submitOrder" class="jayasuriyapractice.SubmitOrderTest"/>
      </group> <!-- Purchase -->
      <group name="ErrorHandling">
        <method signature="ErrorValidationsTest.LoginErrorValidation()[pri:0, instance:jayasuriyapractice.ErrorValidationsTest@4f0100a7]" name="LoginErrorValidation" class="jayasuriyapractice.ErrorValidationsTest"/>
      </group> <!-- ErrorHandling -->
    </groups>
    <test started-at="2024-03-01T07:24:48Z" name="Submit Order Test" finished-at="2024-03-01T07:24:48Z" duration-ms="102">
      <class name="jayasuriyapractice.SubmitOrderTest">
        <test-method signature="submitOrder(java.util.HashMap)[pri:0, instance:jayasuriyapractice.SubmitOrderTest@21337f7b]" started-at="2024-03-01T12:54:48Z" name="submitOrder" data-provider="getData" finished-at="2024-03-01T12:54:48Z" duration-ms="0" status="SKIP">
          <exception class="java.lang.RuntimeException">
            <message>
              <![CDATA[java.nio.file.NoSuchFileException: C:\Users\jayasus\JavaSelenium\SeleniumFrameworkDesign\src\test\java\jayasuriyapractice\data\PurchaseOrder.json]]>
            </message>
            <full-stacktrace>
              <![CDATA[java.lang.RuntimeException: java.nio.file.NoSuchFileException: C:\Users\jayasus\JavaSelenium\SeleniumFrameworkDesign\src\test\java\jayasuriyapractice\data\PurchaseOrder.json
	at org.testng.internal.MethodInvocationHelper.invokeMethodNoCheckedException(MethodInvocationHelper.java:49)
	at org.testng.internal.MethodInvocationHelper.invokeDataProvider(MethodInvocationHelper.java:115)
	at org.testng.internal.Parameters.handleParameters(Parameters.java:509)
	at org.testng.internal.Invoker.handleParameters(Invoker.java:1308)
	at org.testng.internal.Invoker.createParameters(Invoker.java:1036)
	at org.testng.internal.Invoker.invokeTestMethods(Invoker.java:1126)
	at org.testng.internal.TestMethodWorker.invokeTestMethods(TestMethodWorker.java:126)
	at org.testng.internal.TestMethodWorker.run(TestMethodWorker.java:109)
	at org.testng.TestRunner.privateRun(TestRunner.java:744)
	at org.testng.TestRunner.run(TestRunner.java:602)
	at org.testng.SuiteRunner.runTest(SuiteRunner.java:380)
	at org.testng.SuiteRunner.access$000(SuiteRunner.java:39)
	at org.testng.SuiteRunner$SuiteWorker.run(SuiteRunner.java:414)
	at org.testng.internal.thread.ThreadUtil$1.call(ThreadUtil.java:52)
	at java.base/java.util.concurrent.FutureTask.run(FutureTask.java:264)
	at java.base/java.util.concurrent.ThreadPoolExecutor.runWorker(ThreadPoolExecutor.java:1136)
	at java.base/java.util.concurrent.ThreadPoolExecutor$Worker.run(ThreadPoolExecutor.java:635)
	at java.base/java.lang.Thread.run(Thread.java:840)
Caused by: java.nio.file.NoSuchFileException: C:\Users\jayasus\JavaSelenium\SeleniumFrameworkDesign\src\test\java\jayasuriyapractice\data\PurchaseOrder.json
	at java.base/sun.nio.fs.WindowsException.translateToIOException(WindowsException.java:85)
	at java.base/sun.nio.fs.WindowsException.rethrowAsIOException(WindowsException.java:103)
	at java.base/sun.nio.fs.WindowsException.rethrowAsIOException(WindowsException.java:108)
	at java.base/sun.nio.fs.WindowsFileSystemProvider.newByteChannel(WindowsFileSystemProvider.java:236)
	at java.base/java.nio.file.Files.newByteChannel(Files.java:380)
	at java.base/java.nio.file.Files.newByteChannel(Files.java:432)
	at java.base/java.nio.file.spi.FileSystemProvider.newInputStream(FileSystemProvider.java:422)
	at java.base/java.nio.file.Files.newInputStream(Files.java:160)
	at org.apache.commons.io.FileUtils.lambda$readFileToString$12(FileUtils.java:2616)
	at org.apache.commons.io.IOUtils.toString(IOUtils.java:3177)
	at org.apache.commons.io.IOUtils.toString(IOUtils.java:3152)
	at org.apache.commons.io.FileUtils.readFileToString(FileUtils.java:2616)
	at jayasuriyapractice.Testcomponents.BaseTest.getJsonDataToMap(BaseTest.java:75)
	at jayasuriyapractice.SubmitOrderTest.getData(SubmitOrderTest.java:63)
	at java.base/jdk.internal.reflect.NativeMethodAccessorImpl.invoke0(Native Method)
	at java.base/jdk.internal.reflect.NativeMethodAccessorImpl.invoke(NativeMethodAccessorImpl.java:77)
	at java.base/jdk.internal.reflect.DelegatingMethodAccessorImpl.invoke(DelegatingMethodAccessorImpl.java:43)
	at java.base/java.lang.reflect.Method.invoke(Method.java:568)
	at org.testng.internal.MethodInvocationHelper.invokeMethod(MethodInvocationHelper.java:108)
	at org.testng.internal.MethodInvocationHelper.invokeMethod(MethodInvocationHelper.java:55)
	at org.testng.internal.MethodInvocationHelper.invokeMethodNoCheckedException(MethodInvocationHelper.java:45)
	... 17 more
]]>
            </full-stacktrace>
          </exception> <!-- java.lang.RuntimeException -->
          <reporter-output>
          </reporter-output>
        </test-method> <!-- submitOrder -->
        <test-method signature="OrderHistoryTest()[pri:0, instance:jayasuriyapractice.SubmitOrderTest@21337f7b]" started-at="2024-03-01T12:54:48Z" name="OrderHistoryTest" finished-at="2024-03-01T12:54:48Z" depends-on-methods="jayasuriyapractice.SubmitOrderTest.submitOrder" duration-ms="0" status="SKIP">
          <exception class="java.lang.Throwable">
            <message>
              <![CDATA[Method SubmitOrderTest.OrderHistoryTest()[pri:0, instance:jayasuriyapractice.SubmitOrderTest@21337f7b] depends on not successfully finished methods]]>
            </message>
            <full-stacktrace>
              <![CDATA[java.lang.Throwable: Method SubmitOrderTest.OrderHistoryTest()[pri:0, instance:jayasuriyapractice.SubmitOrderTest@21337f7b] depends on not successfully finished methods
	at org.testng.internal.Invoker.invokeTestMethods(Invoker.java:1084)
	at org.testng.internal.TestMethodWorker.invokeTestMethods(TestMethodWorker.java:126)
	at org.testng.internal.TestMethodWorker.run(TestMethodWorker.java:109)
	at org.testng.TestRunner.privateRun(TestRunner.java:744)
	at org.testng.TestRunner.run(TestRunner.java:602)
	at org.testng.SuiteRunner.runTest(SuiteRunner.java:380)
	at org.testng.SuiteRunner.access$000(SuiteRunner.java:39)
	at org.testng.SuiteRunner$SuiteWorker.run(SuiteRunner.java:414)
	at org.testng.internal.thread.ThreadUtil$1.call(ThreadUtil.java:52)
	at java.base/java.util.concurrent.FutureTask.run(FutureTask.java:264)
	at java.base/java.util.concurrent.ThreadPoolExecutor.runWorker(ThreadPoolExecutor.java:1136)
	at java.base/java.util.concurrent.ThreadPoolExecutor$Worker.run(ThreadPoolExecutor.java:635)
	at java.base/java.lang.Thread.run(Thread.java:840)
]]>
            </full-stacktrace>
          </exception> <!-- java.lang.Throwable -->
          <reporter-output>
          </reporter-output>
        </test-method> <!-- OrderHistoryTest -->
      </class> <!-- jayasuriyapractice.SubmitOrderTest -->
    </test> <!-- Submit Order Test -->
    <test started-at="2024-03-01T07:24:48Z" name="Error Validations Test" finished-at="2024-03-01T07:25:09Z" duration-ms="21730">
      <class name="jayasuriyapractice.ErrorValidationsTest">
        <test-method is-config="true" signature="launchApplication()[pri:0, instance:jayasuriyapractice.ErrorValidationsTest@4f0100a7]" started-at="2024-03-01T12:54:48Z" name="launchApplication" finished-at="2024-03-01T12:54:55Z" duration-ms="7163" status="PASS">
          <reporter-output>
          </reporter-output>
        </test-method> <!-- launchApplication -->
        <test-method signature="LoginErrorValidation()[pri:0, instance:jayasuriyapractice.ErrorValidationsTest@4f0100a7]" started-at="2024-03-01T12:54:55Z" name="LoginErrorValidation" finished-at="2024-03-01T12:54:56Z" duration-ms="858" status="SKIP">
          <exception class="java.lang.AssertionError">
            <message>
              <![CDATA[expected [Incorrect email or password.] but found [Incorrect email  password.]]]>
            </message>
            <full-stacktrace>
              <![CDATA[java.lang.AssertionError: expected [Incorrect email or password.] but found [Incorrect email  password.]
	at org.testng.Assert.fail(Assert.java:93)
	at org.testng.Assert.failNotEquals(Assert.java:512)
	at org.testng.Assert.assertEqualsImpl(Assert.java:134)
	at org.testng.Assert.assertEquals(Assert.java:115)
	at org.testng.Assert.assertEquals(Assert.java:189)
	at org.testng.Assert.assertEquals(Assert.java:199)
	at jayasuriyapractice.ErrorValidationsTest.LoginErrorValidation(ErrorValidationsTest.java:22)
	at java.base/jdk.internal.reflect.NativeMethodAccessorImpl.invoke0(Native Method)
	at java.base/jdk.internal.reflect.NativeMethodAccessorImpl.invoke(NativeMethodAccessorImpl.java:77)
	at java.base/jdk.internal.reflect.DelegatingMethodAccessorImpl.invoke(DelegatingMethodAccessorImpl.java:43)
	at java.base/java.lang.reflect.Method.invoke(Method.java:568)
	at org.testng.internal.MethodInvocationHelper.invokeMethod(MethodInvocationHelper.java:108)
	at org.testng.internal.Invoker.invokeMethod(Invoker.java:661)
	at org.testng.internal.Invoker.invokeTestMethod(Invoker.java:869)
	at org.testng.internal.Invoker.invokeTestMethods(Invoker.java:1193)
	at org.testng.internal.TestMethodWorker.invokeTestMethods(TestMethodWorker.java:126)
	at org.testng.internal.TestMethodWorker.run(TestMethodWorker.java:109)
	at org.testng.TestRunner.privateRun(TestRunner.java:744)
	at org.testng.TestRunner.run(TestRunner.java:602)
	at org.testng.SuiteRunner.runTest(SuiteRunner.java:380)
	at org.testng.SuiteRunner.access$000(SuiteRunner.java:39)
	at org.testng.SuiteRunner$SuiteWorker.run(SuiteRunner.java:414)
	at org.testng.internal.thread.ThreadUtil$1.call(ThreadUtil.java:52)
	at java.base/java.util.concurrent.FutureTask.run(FutureTask.java:264)
	at java.base/java.util.concurrent.ThreadPoolExecutor.runWorker(ThreadPoolExecutor.java:1136)
	at java.base/java.util.concurrent.ThreadPoolExecutor$Worker.run(ThreadPoolExecutor.java:635)
	at java.base/java.lang.Thread.run(Thread.java:840)
]]>
            </full-stacktrace>
          </exception> <!-- java.lang.AssertionError -->
          <reporter-output>
          </reporter-output>
        </test-method> <!-- LoginErrorValidation -->
        <test-method is-config="true" signature="tearDown()[pri:0, instance:jayasuriyapractice.ErrorValidationsTest@4f0100a7]" started-at="2024-03-01T12:54:56Z" name="tearDown" finished-at="2024-03-01T12:54:56Z" duration-ms="316" status="PASS">
          <reporter-output>
          </reporter-output>
        </test-method> <!-- tearDown -->
        <test-method is-config="true" signature="launchApplication()[pri:0, instance:jayasuriyapractice.ErrorValidationsTest@4f0100a7]" started-at="2024-03-01T12:54:56Z" name="launchApplication" finished-at="2024-03-01T12:55:00Z" duration-ms="4322" status="PASS">
          <reporter-output>
          </reporter-output>
        </test-method> <!-- launchApplication -->
        <test-method signature="LoginErrorValidation()[pri:0, instance:jayasuriyapractice.ErrorValidationsTest@4f0100a7]" started-at="2024-03-01T12:55:00Z" name="LoginErrorValidation" finished-at="2024-03-01T12:55:01Z" duration-ms="792" status="FAIL">
          <exception class="java.lang.AssertionError">
            <message>
              <![CDATA[expected [Incorrect email or password.] but found [Incorrect email  password.]]]>
            </message>
            <full-stacktrace>
              <![CDATA[java.lang.AssertionError: expected [Incorrect email or password.] but found [Incorrect email  password.]
	at org.testng.Assert.fail(Assert.java:93)
	at org.testng.Assert.failNotEquals(Assert.java:512)
	at org.testng.Assert.assertEqualsImpl(Assert.java:134)
	at org.testng.Assert.assertEquals(Assert.java:115)
	at org.testng.Assert.assertEquals(Assert.java:189)
	at org.testng.Assert.assertEquals(Assert.java:199)
	at jayasuriyapractice.ErrorValidationsTest.LoginErrorValidation(ErrorValidationsTest.java:22)
	at java.base/jdk.internal.reflect.NativeMethodAccessorImpl.invoke0(Native Method)
	at java.base/jdk.internal.reflect.NativeMethodAccessorImpl.invoke(NativeMethodAccessorImpl.java:77)
	at java.base/jdk.internal.reflect.DelegatingMethodAccessorImpl.invoke(DelegatingMethodAccessorImpl.java:43)
	at java.base/java.lang.reflect.Method.invoke(Method.java:568)
	at org.testng.internal.MethodInvocationHelper.invokeMethod(MethodInvocationHelper.java:108)
	at org.testng.internal.Invoker.invokeMethod(Invoker.java:661)
	at org.testng.internal.Invoker.retryFailed(Invoker.java:1014)
	at org.testng.internal.Invoker.invokeTestMethods(Invoker.java:1215)
	at org.testng.internal.TestMethodWorker.invokeTestMethods(TestMethodWorker.java:126)
	at org.testng.internal.TestMethodWorker.run(TestMethodWorker.java:109)
	at org.testng.TestRunner.privateRun(TestRunner.java:744)
	at org.testng.TestRunner.run(TestRunner.java:602)
	at org.testng.SuiteRunner.runTest(SuiteRunner.java:380)
	at org.testng.SuiteRunner.access$000(SuiteRunner.java:39)
	at org.testng.SuiteRunner$SuiteWorker.run(SuiteRunner.java:414)
	at org.testng.internal.thread.ThreadUtil$1.call(ThreadUtil.java:52)
	at java.base/java.util.concurrent.FutureTask.run(FutureTask.java:264)
	at java.base/java.util.concurrent.ThreadPoolExecutor.runWorker(ThreadPoolExecutor.java:1136)
	at java.base/java.util.concurrent.ThreadPoolExecutor$Worker.run(ThreadPoolExecutor.java:635)
	at java.base/java.lang.Thread.run(Thread.java:840)
]]>
            </full-stacktrace>
          </exception> <!-- java.lang.AssertionError -->
          <reporter-output>
          </reporter-output>
        </test-method> <!-- LoginErrorValidation -->
        <test-method is-config="true" signature="tearDown()[pri:0, instance:jayasuriyapractice.ErrorValidationsTest@4f0100a7]" started-at="2024-03-01T12:55:02Z" name="tearDown" finished-at="2024-03-01T12:55:02Z" duration-ms="311" status="PASS">
          <reporter-output>
          </reporter-output>
        </test-method> <!-- tearDown -->
        <test-method is-config="true" signature="launchApplication()[pri:0, instance:jayasuriyapractice.ErrorValidationsTest@4f0100a7]" started-at="2024-03-01T12:55:02Z" name="launchApplication" finished-at="2024-03-01T12:55:06Z" duration-ms="4220" status="PASS">
          <reporter-output>
          </reporter-output>
        </test-method> <!-- launchApplication -->
        <test-method signature="ProductErrorValidation()[pri:0, instance:jayasuriyapractice.ErrorValidationsTest@4f0100a7]" started-at="2024-03-01T12:55:06Z" name="ProductErrorValidation" finished-at="2024-03-01T12:55:09Z" duration-ms="2716" status="PASS">
          <reporter-output>
          </reporter-output>
        </test-method> <!-- ProductErrorValidation -->
        <test-method is-config="true" signature="tearDown()[pri:0, instance:jayasuriyapractice.ErrorValidationsTest@4f0100a7]" started-at="2024-03-01T12:55:09Z" name="tearDown" finished-at="2024-03-01T12:55:09Z" duration-ms="390" status="PASS">
          <reporter-output>
          </reporter-output>
        </test-method> <!-- tearDown -->
      </class> <!-- jayasuriyapractice.ErrorValidationsTest -->
    </test> <!-- Error Validations Test -->
  </suite> <!-- Suite -->
</testng-results>
